Workbook

Sheet Raw Data
A1: order_id | B1: order_date | C1: customer_name | D1: region | E1: product_category | F1: product_name | G1: quantity | H1: unit_price | I1: revenue
A2: ORD-001 | B2: 2024-03-04 | C2: Henry Davis | D2: South | E2: Electronics | F2: Wireless Headphones | G2: 9 | H2: 89.99 | I2: 809.91
A3: ORD-002 | B3: 03/04/2024 | C3: Sam White | D3: North | E3: Sports | F3: Water Bottle | G3: 3 | H3: 19.99 | I3: 59.97
A4: ORD-003 | B4: 03-Jan-2024 | C4: Quinn Clark | D4: North | E4: Clothing | F4: Running Shorts | G4: 8 | H4: 34.99 | I4: 279.92
A5: ORD-004 | B5: 2024-03-07 | C5: Henry Harris | D5: East | E5: Sports | F5: Water Bottle | G5: 14 | H5: 19.99 | I5: 279.86
A6: ORD-005 | B6: 01/25/2024 | C6: Karen Wilson | D6: South | E6: Clothing | F6: Fleece Jacket | G6: 14 | H6: 74.99
A7: ORD-006 | B7: 25-Jan-2024 | C7: Carol Jackson | D7: North | E7: Home & Garden | F7: Garden Hose | G7: 4 | H7: 44.99 | I7: 179.96
A8: ORD-007 | B8: 2024-02-28 | C8: Isabel Johnson | D8: West | E8: Home & Garden | F8: Throw Pillow Set | G8: 20 | H8: 39.99 | I8: 799.8
A9: ORD-008 | B9: 03/04/2024 | C9: Rachel Taylor | D9: East | E9: Home & Garden | F9: Scented Candles | G9: 3 | H9: 24.99 | I9: 74.97
A10: ORD-009 | B10: 07-Mar-2024 | C10: Henry Taylor | D10: North | E10: Electronics | F10: Portable Charger | G10: 2 | H10: 29.99 | I10: 59.98
A11: ORD-010 | B11: 2024-01-28 | C11: Isabel Harris | D11: East | E11: Electronics | F11: Bluetooth Speaker | G11: 13 | H11: 59.99 | I11: 779.87
A12: ORD-010 | B12: 01/28/2024 | C12: Isabel Harris | D12: East | E12: Electronics | F12: Bluetooth Speaker | G12: 13 | H12: 59.99 | I12: 779.87
A13: ORD-011 | B13: 12-Jan-2024 | C13: Isabel Williams | D13: South | E13: Home & Garden | F13: Throw Pillow Set | G13: 7 | H13: 39.99 | I13: 279.93
A14: ORD-012 | B14: 2024-03-24 | C14: Olivia Jackson | D14: East | E14: Clothing | F14: Waterproof Boots | G14: 6 | H14: 119.99 | I14: 719.94
A15: ORD-013 | B15: 03/23/2024 | C15: Karen Johnson | D15: South | E15: Sports | F15: Water Bottle | G15: 8 | H15: 19.99 | I15: 159.92
A16: ORD-014 | B16: 26-Jan-2024 | C16: Isabel Williams | D16: South | E16: Home & Garden | F16: Garden Hose | G16: 13 | H16: 44.99
A17: ORD-015 | B17: 2024-03-23 | C17: Peter Jackson | D17: West | E17: Home & Garden | F17: Garden Hose | G17: 7 | H17: 44.99 | I17: 314.93
A18: ORD-016 | B18: 01/09/2024 | C18: Rachel Moore | D18: East | E18: Electronics | F18: Smart Watch | G18: 8 | H18: 199.99 | I18: 1599.92
A19: ORD-017 | B19: 19-Mar-2024 | C19: Maya Thomas | D19: South | E19: Home & Garden | F19: Wall Clock | G19: 19 | H19: 34.99 | I19: 664.81
A20: ORD-018 | B20: 2024-01-17 | C20: Bob Brown | D20: South | E20: Sports | F20: Yoga Mat | G20: 3 | H20: 49.99 | I20: 149.97
A21: ORD-019 | B21: 03/06/2024 | C21: Carol Jackson | D21: West | E21: Home & Garden | F21: Wall Clock | G21: 20 | H21: 34.99 | I21: 699.8
A22: ORD-020 | B22: 15-Mar-2024 | C22: Rachel Smith | D22: North | E22: Sports | F22: Resistance Bands | G22: 9 | H22: 24.99 | I22: 224.91
A23: ORD-021 | B23: 2024-03-18 | C23: David Taylor | D23: West | E23: Clothing | F23: Casual T-Shirt | G23: 11 | H23: 19.99 | I23: 219.89
A24: ORD-022 | B24: 01/15/2024 | C24: Quinn Garcia | D24: North | E24: Electronics | F24: Wireless Headphones | G24: 9 | H24: 89.99 | I24: 809.91
A25: ORD-022 | B25: 15-Jan-2024 | C25: Quinn Garcia | D25: North | E25: Electronics | F25: Wireless Headphones | G25: 9 | H25: 89.99 | I25: 809.91
A26: ORD-023 | B26: 2024-03-10 | C26: Grace Jones | D26: East | E26: Sports | F26: Resistance Bands | G26: 20 | H26: 24.99 | I26: 499.8
A27: ORD-024 | B27: 01/18/2024 | C27: Tara Anderson | D27: West | E27: Sports | F27: Resistance Bands | G27: 1 | H27: 24.99 | I27: 24.99
A28: ORD-025 | B28: 04-Jan-2024 | C28: Henry Johnson | D28: South | E28: Home & Garden | F28: Throw Pillow Set | G28: 10 | H28: 39.99
A29: ORD-026 | B29: 2024-03-03 | C29: Carol Moore | D29: South | E29: Electronics | F29: Portable Charger | G29: 16 | H29: 29.99 | I29: 479.84
A30: ORD-027 | B30: 01/22/2024 | C30: Frank Wilson | D30: West | E30: Sports | F30: Yoga Mat | G30: 18 | H30: 49.99 | I30: 899.82
A31: ORD-028 | B31: 18-Jan-2024 | C31: Maya Thomas | D31: West | E31: Clothing | F31: Running Shorts | G31: 10 | H31: 34.99 | I31: 349.9
A32: ORD-029 | B32: 2024-03-15 | C32: Henry Williams | D32: East | E32: Electronics | F32: Bluetooth Speaker | G32: 8 | H32: 59.99 | I32: 479.92
A33: ORD-030 | B33: 01/19/2024 | C33: Sam Davis | D33: North | E33: Sports | F33: Water Bottle | G33: 8 | H33: 19.99 | I33: 159.92
A34: ORD-031 | B34: 23-Jan-2024 | C34: Carol Johnson | D34: East | E34: Electronics | F34: USB-C Hub | G34: 8 | H34: 34.99 | I34: 279.92
A35: ORD-032 | B35: 2024-01-17 | C35: Peter Miller | D35: South | E35: Clothing | F35: Waterproof Boots | G35: 9 | H35: 119.99 | I35: 1079.91
A36: ORD-033 | B36: 03/19/2024 | C36: Henry Martin | D36: West | E36: Sports | F36: Foam Roller | G36: 16 | H36: 34.99
A37: ORD-034 | B37: 04-Jan-2024 | C37: Liam White | D37: West | E37: Electronics | F37: Bluetooth Speaker | G37: 14 | H37: 59.99 | I37: 839.86
A38: ORD-035 | B38: 2024-02-28 | C38: Bob Jackson | D38: East | E38: Electronics | F38: USB-C Hub | G38: 4 | H38: 34.99 | I38: 139.96
A39: ORD-035 | B39: 02/28/2024 | C39: Bob Jackson | D39: East | E39: Electronics | F39: USB-C Hub | G39: 4 | H39: 34.99 | I39: 139.96
A40: ORD-036 | B40: 08-Jan-2024 | C40: Rachel Harris | D40: South | E40: Clothing | F40: Running Shorts | G40: 7 | H40: 34.99 | I40: 244.93
...

Sheet Cleaned Data
A1: order_id | B1: order_date | C1: customer_name | D1: region | E1: product_category | F1: product_name | G1: quantity | H1: unit_price | I1: revenue
A2: ORD-001 | B2: 2024-03-04 | C2: Henry Davis | D2: South | E2: Electronics | F2: Wireless Headphones | G2: 9 | H2: 89.99 | I2: =G2*H2 -> 809.91
A3: ORD-002 | B3: 2024-03-04 | C3: Sam White | D3: North | E3: Sports | F3: Water Bottle | G3: 3 | H3: 19.99 | I3: =G3*H3 -> 59.97
A4: ORD-003 | B4: 2024-01-03 | C4: Quinn Clark | D4: North | E4: Clothing | F4: Running Shorts | G4: 8 | H4: 34.99 | I4: =G4*H4 -> 279.92
A5: ORD-004 | B5: 2024-03-07 | C5: Henry Harris | D5: East | E5: Sports | F5: Water Bottle | G5: 14 | H5: 19.99 | I5: =G5*H5 -> 279.86
A6: ORD-005 | B6: 2024-01-25 | C6: Karen Wilson | D6: South | E6: Clothing | F6: Fleece Jacket | G6: 14 | H6: 74.99 | I6: =G6*H6 -> 1049.86
A7: ORD-006 | B7: 2024-01-25 | C7: Carol Jackson | D7: North | E7: Home & Garden | F7: Garden Hose | G7: 4 | H7: 44.99 | I7: =G7*H7 -> 179.96
A8: ORD-007 | B8: 2024-02-28 | C8: Isabel Johnson | D8: West | E8: Home & Garden | F8: Throw Pillow Set | G8: 20 | H8: 39.99 | I8: =G8*H8 -> 799.8
A9: ORD-008 | B9: 2024-03-04 | C9: Rachel Taylor | D9: East | E9: Home & Garden | F9: Scented Candles | G9: 3 | H9: 24.99 | I9: =G9*H9 -> 74.97
A10: ORD-009 | B10: 2024-03-07 | C10: Henry Taylor | D10: North | E10: Electronics | F10: Portable Charger | G10: 2 | H10: 29.99 | I10: =G10*H10 -> 59.98
A11: ORD-010 | B11: 2024-01-28 | C11: Isabel Harris | D11: East | E11: Electronics | F11: Bluetooth Speaker | G11: 13 | H11: 59.99 | I11: =G11*H11 -> 779.87
A12: ORD-011 | B12: 2024-01-12 | C12: Isabel Williams | D12: South | E12: Home & Garden | F12: Throw Pillow Set | G12: 7 | H12: 39.99 | I12: =G12*H12 -> 279.93
A13: ORD-012 | B13: 2024-03-24 | C13: Olivia Jackson | D13: East | E13: Clothing | F13: Waterproof Boots | G13: 6 | H13: 119.99 | I13: =G13*H13 -> 719.94
... A71: ORD-070 | B71: 2024-03-26 | C71: Liam White | D71: North | E71: Sports | F71: Water Bottle | G71: 7 | H71: 19.99 | I71: =G71*H71 -> 139.93

Sheet Summary
A1: NorthWave Retail — Q1 2024 Sales Summary
A3: DATA QUALITY
A4: Total orders (raw) | B4: =COUNTA('Raw Data'!A2:A76) -> 75
A5: Duplicate orders removed | B5: 5
A6: Revenue nulls filled | B6: 8
A7: Total orders (cleaned) | B7: =COUNTA('Cleaned Data'!A2:A71) -> 70
A9: REVENUE OVERVIEW
A10: Total revenue | B10: =SUM('Cleaned Data'!I2:I71) -> 34402.77
A11: Average order value | B11: =AVERAGE('Cleaned Data'!I2:I71) -> 491.46814
A12: Total units sold | B12: =SUM('Cleaned Data'!G2:G71) -> 723
A14: REVENUE BY REGION
A15: North | B15: =SUMIF('Cleaned Data'!D$2:D$71,"North",'Cleaned Data'!I$2:I$71) -> 7378.15
A16: South | B16: =SUMIF('Cleaned Data'!D$2:D$71,"South",'Cleaned Data'!I$2:I$71) -> 7638.33
A17: East | B17: =SUMIF('Cleaned Data'!D$2:D$71,"East",'Cleaned Data'!I$2:I$71) -> 11907.95
A18: West | B18: =SUMIF('Cleaned Data'!D$2:D$71,"West",'Cleaned Data'!I$2:I$71) -> 7478.34
A20: REVENUE BY PRODUCT CATEGORY
A21: Electronics | B21: =SUMIF('Cleaned Data'!E$2:E$71,"Electronics",'Cleaned Data'!I$2:I$71) -> 11348.42
A22: Clothing | B22: =SUMIF('Cleaned Data'!E$2:E$71,"Clothing",'Cleaned Data'!I$2:I$71) -> 9248.45
A23: Home & Garden | B23: =SUMIF('Cleaned Data'!E$2:E$71,"Home & Garden",'Cleaned Data'!I$2:I$71) -> 6328.29
A24: Sports | B24: =SUMIF('Cleaned Data'!E$2:E$71,"Sports",'Cleaned Data'!I$2:I$71) -> 7477.61
A26: ORDER COUNT BY REGION
A27: North | B27: =COUNTIF('Cleaned Data'!D$2:D$71,"North") -> 19
A28: South | B28: =COUNTIF('Cleaned Data'!D$2:D$71,"South") -> 17
A29: East | B29: =COUNTIF('Cleaned Data'!D$2:D$71,"East") -> 19
A30: West | B30: =COUNTIF('Cleaned Data'!D$2:D$71,"West") -> 15
